[2023-09-10T19:53:09.626+0530] {taskinstance.py:1157} INFO - Dependencies all met for dep_context=non-requeueable deps ti=<TaskInstance: csv_to_postgresql.csv_to_postgresql_task scheduled__2023-09-07T00:00:00+00:00 [queued]>
[2023-09-10T19:53:09.629+0530] {taskinstance.py:1157} INFO - Dependencies all met for dep_context=requeueable deps ti=<TaskInstance: csv_to_postgresql.csv_to_postgresql_task scheduled__2023-09-07T00:00:00+00:00 [queued]>
[2023-09-10T19:53:09.630+0530] {taskinstance.py:1359} INFO - Starting attempt 1 of 1
[2023-09-10T19:53:09.636+0530] {taskinstance.py:1380} INFO - Executing <Task(PythonOperator): csv_to_postgresql_task> on 2023-09-07 00:00:00+00:00
[2023-09-10T19:53:09.639+0530] {standard_task_runner.py:57} INFO - Started process 53658 to run task
[2023-09-10T19:53:09.643+0530] {standard_task_runner.py:84} INFO - Running: ['airflow', 'tasks', 'run', 'csv_to_postgresql', 'csv_to_postgresql_task', 'scheduled__2023-09-07T00:00:00+00:00', '--job-id', '17', '--raw', '--subdir', 'DAGS_FOLDER/apache_task.py', '--cfg-path', '/var/folders/fl/qmmrk2fj1nnfxf9xj8fmmmf40000gp/T/tmpgbhcg54r']
[2023-09-10T19:53:09.644+0530] {standard_task_runner.py:85} INFO - Job 17: Subtask csv_to_postgresql_task
[2023-09-10T19:53:09.667+0530] {task_command.py:415} INFO - Running <TaskInstance: csv_to_postgresql.csv_to_postgresql_task scheduled__2023-09-07T00:00:00+00:00 [running]> on host ip-192-168-1-105.us-west-2.compute.internal
[2023-09-10T19:53:09.686+0530] {taskinstance.py:1660} INFO - Exporting env vars: AIRFLOW_CTX_DAG_OWNER='rajiv.chavan' AIRFLOW_CTX_DAG_ID='csv_to_postgresql' AIRFLOW_CTX_TASK_ID='csv_to_postgresql_task' AIRFLOW_CTX_EXECUTION_DATE='2023-09-07T00:00:00+00:00' AIRFLOW_CTX_TRY_NUMBER='1' AIRFLOW_CTX_DAG_RUN_ID='scheduled__2023-09-07T00:00:00+00:00'
[2023-09-10T19:53:09.687+0530] {taskinstance.py:1935} ERROR - Task failed with exception
Traceback (most recent call last):
  File "/Users/work/python/new_csv_insertion/env/lib/python3.11/site-packages/airflow/operators/python.py", line 192, in execute
    return_value = self.execute_callable()
                   ^^^^^^^^^^^^^^^^^^^^^^^
  File "/Users/work/python/new_csv_insertion/env/lib/python3.11/site-packages/airflow/operators/python.py", line 209, in execute_callable
    return self.python_callable(*self.op_args, **self.op_kwargs)
           ^^^^^^^^^^^^^^^^^^^^^^^^^^^^^^^^^^^^^^^^^^^^^^^^^^^^^
  File "/Users/work/airflow/dags/task.py", line 52, in main
    data = csv_to_postgresql.extract_data()
           ^^^^^^^^^^^^^^^^^^^^^^^^^^^^^^^^
  File "/Users/work/airflow/dags/task.py", line 12, in extract_data
    data = pd.read_csv(self.csv_file)
           ^^^^^^^^^^^^^^^^^^^^^^^^^^
  File "/Users/work/python/new_csv_insertion/env/lib/python3.11/site-packages/pandas/io/parsers/readers.py", line 948, in read_csv
    return _read(filepath_or_buffer, kwds)
           ^^^^^^^^^^^^^^^^^^^^^^^^^^^^^^^
  File "/Users/work/python/new_csv_insertion/env/lib/python3.11/site-packages/pandas/io/parsers/readers.py", line 611, in _read
    parser = TextFileReader(filepath_or_buffer, **kwds)
             ^^^^^^^^^^^^^^^^^^^^^^^^^^^^^^^^^^^^^^^^^^
  File "/Users/work/python/new_csv_insertion/env/lib/python3.11/site-packages/pandas/io/parsers/readers.py", line 1448, in __init__
    self._engine = self._make_engine(f, self.engine)
                   ^^^^^^^^^^^^^^^^^^^^^^^^^^^^^^^^^
  File "/Users/work/python/new_csv_insertion/env/lib/python3.11/site-packages/pandas/io/parsers/readers.py", line 1705, in _make_engine
    self.handles = get_handle(
                   ^^^^^^^^^^^
  File "/Users/work/python/new_csv_insertion/env/lib/python3.11/site-packages/pandas/io/common.py", line 863, in get_handle
    handle = open(
             ^^^^^
FileNotFoundError: [Errno 2] No such file or directory: 'organizations-100.csv'
[2023-09-10T19:53:09.690+0530] {taskinstance.py:1398} INFO - Marking task as FAILED. dag_id=csv_to_postgresql, task_id=csv_to_postgresql_task, execution_date=20230907T000000, start_date=20230910T142309, end_date=20230910T142309
[2023-09-10T19:53:09.693+0530] {standard_task_runner.py:104} ERROR - Failed to execute job 17 for task csv_to_postgresql_task ([Errno 2] No such file or directory: 'organizations-100.csv'; 53658)
[2023-09-10T19:53:09.699+0530] {local_task_job_runner.py:228} INFO - Task exited with return code 1
[2023-09-10T19:53:09.704+0530] {taskinstance.py:2776} INFO - 0 downstream tasks scheduled from follow-on schedule check
